Workbook

Sheet Entreprises
A1: Entreprise | B1: Enseigne / nom commercial | C1: SIREN | D1: Activité (NAF) | E1: Code NAF | F1: Secteur | G1: Effectif local | H1: Effectif entreprise | I1: Catégorie | J1: Forme juridique | K1: Adresse | L1: Code postal | M1: Commune | N1: Distance Rennes (km) | O1: Étab. 10+ dans la zone | P1: Siège | Q1: Email pour candidater | R1: Email RH / recrutement | S1: Email SI / informatique | T1: Email contact général | U1: Page carrières / candidature | V1: Site web | W1: Source des emails | X1: Statut
A2: KEOLIS RENNES | C2: 340035526 | D2: Transports urbains et suburbains de voyageurs | E2: 49.31Z | F2: Transports et entreposage | G2: 1 000-1 999 | H2: 1 000-1 999 | I2: GE | J2: SA | K2: PLAINE DE BAUD RUE JEAN-MARIE HUCHET 35000 RENNES | L2: 35000 | M2: RENNES | N2: 2.7 | O2: 1 | P2: Dans la zone | V2: https://www.star.fr | X2: Site analysé, aucun email publié
A3: ORANGE | B3: CTRE COMMUN D'ETUDES ET DE TELEDIFFUSION | C3: 380129866 | D3: Télécommunications filaires | E3: 61.10Z | F3: Information et communication | G3: 1 000-1 999 | H3: 10 000 et + | I3: GE | J3: SA | K3: 4 RUE DU CLOS COURTEL 35510 CESSON-SEVIGNE | L3: 35510 | M3: CESSON-SEVIGNE | N3: 4.2 | O3: 1 | P3: Hors zone (Issy-Les-Moulineaux) | V3: https://www.orange.com/ | X3: Site analysé, aucun email publié
A4: CAPGEMINI TECHNOLOGY SERVICES | C4: 479766842 | D4: Conseil en systèmes et logiciels informatiques | E4: 62.02A | F4: Information et communication | G4: 1 000-1 999 | H4: 10 000 et + | I4: GE | J4: SAS | K4: LES CHAMPS BLANCS 7 RUE CLAUDE CHAPPE 35510 CESSON-SEVIGNE | L4: 35510 | M4: CESSON-SEVIGNE | N4: 5.1 | O4: 1 | P4: Hors zone (Issy-Les-Moulineaux) | U4: https://www.fr.sogeti.com/carrieres/nous-rejoindre/ | V4: https://www.fr.sogeti.com | X4: Formulaire / site carrières (pas d'email publié)
A5: STELLANTIS AUTO SAS | C5: 542065479 | D5: Construction de véhicules automobiles | E5: 29.10Z | F5: Industrie manufacturière | G5: 1 000-1 999 | H5: 10 000 et + | I5: GE | J5: SAS | K5: USINE LA JANAIS LA JANAIS 35131 CHARTRES-DE-BRETAGNE | L5: 35131 | M5: CHARTRES-DE-BRETAGNE | N5: 6.2 | O5: 1 | P5: Hors zone (Poissy) | X5: Recherché, aucun site trouvé
A6: INNOVAL (URCEO) | C6: 305321929 | D6: Activités de soutien à la production animale | E6: 01.62Z | F6: Agriculture, sylviculture et pêche | G6: 1 000-1 999 | H6: 1 000-1 999 | J6: Coopérative agricole | K6: CS 80038 RUE ERIC TABARLY 35530 NOYAL-SUR-VILAINE | L6: 35530 | M6: NOYAL-SUR-VILAINE | N6: 10.4 | O6: 1 | P6: Dans la zone | X6: Recherché, aucun site trouvé
A7: BRIDOR | C7: 491668893 | D7: Fabrication industrielle de pain et de pâtisserie fraîche | E7: 10.71A | F7: Industrie manufacturière | G7: 1 000-1 999 | H7: 1 000-1 999 | I7: GE | J7: SAS | K7: ZA D'OLIVET 35530 SERVON-SUR-VILAINE | L7: 35530 | M7: SERVON-SUR-VILAINE | N7: 16.5 | O7: 1 | P7: Hors zone (Paris) | X7: Recherché, aucun site trouvé
A8: FONDAT REGION OUEST LIGUE CANCER | C8: 777739160 | D8: Activités hospitalières | E8: 86.10Z | F8: Santé humaine et action sociale | G8: 500-999 | H8: 500-999 | I8: ETI | J8: Fondation | K8: PONCHAILLOU AV BATAILLE FLANDRES DUNKERQUE 35000 RENNES | L8: 35000 | M8: RENNES | N8: 1.6 | O8: 1 | P8: Dans la zone | Q8: communication@rennes.unicancer.fr | T8: communication@rennes.unicancer.fr | U8: https://www.centre-eugene-marquis.fr/professionnels-de-sante/recrutement/ | V8: https://www.centre-eugene-marquis.fr | W8: https://www.centre-eugene-marquis.fr/ | X8: Email de contact général trouvé
A9: CLINIQUE MUTUALISTE DE LA SAGESSE | C9: 775591076 | D9: Activités hospitalières | E9: 86.10Z | F9: Santé humaine et action sociale | G9: 500-999 | H9: 500-999 | I9: ETI | J9: Mutuelle | K9: 4 PLACE SAINT-GUENOLE 35000 RENNES | L9: 35000 | M9: RENNES | N9: 2.7 | O9: 1 | P9: Dans la zone | Q9: accueil@lasagesse.fr | T9: accueil@lasagesse.fr | V9: http://clinique-rennes.fr/ | W9: https://data.rennesmetropole.fr/explore/dataset/sites_organismes_organismes/ | X9: Email de contact général trouvé
A10: LEGENDRE ILE DE FRANCE | C10: 399394204 | D10: Activités des sièges sociaux | E10: 70.10Z | F10: Construction | G10: 500-999 (estim.) | H10: 500-999 | I10: ETI | J10: SAS | K10: 5 RUE LOUIS-JACQUES DAGUERRE 35136 SAINT-JACQUES-DE-LA-LANDE | L10: 35136 | M10: SAINT-JACQUES-DE-LA-LANDE | N10: 2.9 | O10: 1 | P10: Dans la zone | Q10: communication@groupe-legendre.com | T10: communication@groupe-legendre.com | U10: https://careers.groupe-legendre.com/fr | V10: https://www.groupe-legendre.com/ | W10: https://www.groupe-legendre.com/mentions-legales/ | X10: Email de contact général trouvé
A11: HOSPITALITE SAINT THOMAS DE VILLENEUVE (HSTV) | B11: POLYCLINIQUE SAINT LAURENT | C11: 777380783 | D11: Activités hospitalières | E11: 86.10Z | F11: Santé humaine et action sociale | G11: 500-999 | H11: 2 000-4 999 | I11: ETI | J11: Association | K11: CS10610 320 AVENUE GENERAL GEORGE S. PATTON 35700 RENNES | L11: 35700 | M11: RENNES | N11: 3.4 | O11: 4 | P11: Hors zone (Lamballe-Armor) | Q11: contact@polyclinique-saint-laurent.fr | T11: contact@polyclinique-saint-laurent.fr | V11: https://www.polyclinique-saint-laurent.fr/ | W11: https://www.polyclinique-saint-laurent.fr/mentions-legales | X11: Email de contact général trouvé
A12: CENTRE HOSPITALIER PRIVE SAINT GREGOIRE | B12: VIVALTO SANTE LES HOPITAUX PRIVES RENNAIS | C12: 699201323 | D12: Activités hospitalières | E12: 86.10Z | F12: Santé humaine et action sociale | G12: 500-999 | H12: 500-999 | I12: GE | J12: SAS | K12: CS 56816 6 BOULEVARD DE LA BOUTIERE 35760 SAINT-GREGOIRE | L12: 35760 | M12: SAINT-GREGOIRE | N12: 3.7 | O12: 1 | P12: Dans la zone | Q12: stg.contact@vivalto-sante.com | T12: stg.contact@vivalto-sante.com | U12: https://chpsaintgregoire.mstaff.co/offers?type=default | V12: https://www.vivalto-sante.fr/hopitaux-prives-rennais-saint-gregoire/ | W12: https://www.vivalto-sante.fr/hopitaux-prives-rennais-saint-gregoire/mentions-legales | X12: Email de contact général trouvé
A13: CARSAT BRETAGNE | C13: 777749326 | D13: Activités générales de sécurité sociale | E13: 84.30A | F13: Administration publique | G13: 500-999 | H13: 500-999 | I13: ETI | J13: Organisme de sécurité sociale | K13: 236 RUE DE CHATEAUGIRON 35000 RENNES | L13: 35000 | M13: RENNES | N13: 3.7 | O13: 2 | P13: Dans la zone | Q13: drp.formation@carsat-bretagne.fr | T13: drp.formation@carsat-bretagne.fr | W13: https://www.formation.gref-bretagne.com/ (fiche organisme GREF Bretagne) | X13: Email de contact général trouvé
A14: SOCIETE POUR L'INFORMATIQUE INDUSTRIELLE (SII) | C14: 315000943 | D14: Conseil en systèmes et logiciels informatiques | E14: 62.02A | F14: Information et communication | G14: 500-999 | H14: 2 000-4 999 | I14: GE | J14: SA | K14: 3 B AVENUE DE BELLE FONTAINE 35510 CESSON-SEVIGNE | L14: 35510 | M14: CESSON-SEVIGNE | N14: 4.5 | O14: 1 | P14: Hors zone (Paris) | V14: http://www.groupe-sii.com/ | X14: Site analysé, aucun email publié
A15: OBERTHUR FIDUCIAIRE SAS | C15: 803311372 | D15: Autre imprimerie (labeur) | E15: 18.12Z | F15: Industrie manufacturière | G15: 500-999 | H15: 500-999 | I15: ETI | J15: SAS | K15: 20 RUE DU BREIL 35135 CHANTEPIE | L15: 35135 | M15: CHANTEPIE | N15: 4.5 | O15: 1 | P15: Hors zone (Paris) | Q15: job@fcof.com | R15: job@fcof.com | U15: https://www.oberthur-fiduciaire.com/carrieres/ | V15: https://www.oberthur-fiduciaire.com/ | W15: https://www.oberthur-fiduciaire.com/carrieres/ | X15: Email RH / recrutement trouvé
A16: ORANGE BUSINESS SERVICES | C16: 345039416 | D16: Conseil en systèmes et logiciels informatiques | E16: 62.02A | F16: Information et communication | G16: 500-999 | H16: 5 000-9 999 | I16: GE | J16: SA | K16: 9 RUE DU CHENE GERMAIN 35510 CESSON-SEVIGNE | L16: 35510 | M16: CESSON-SEVIGNE | N16: 4.6 | O16: 2 | P16: Hors zone (Saint-Denis) | X16: Recherché, aucun site trouvé
A17: ATALIAN PROPRETE | C17: 399506641 | D17: Nettoyage courant des bâtiments | E17: 81.21Z | F17: Services administratifs et de soutien | G17: 500-999 | H17: 10 000 et + | I17: GE | J17: SAS | K17: ZAC DE LA RIGOURDIERE 28 RUE DE LA RIGOURDIERE 35510 CESSON-SEVIGNE | L17: 35510 | M17: CESSON-SEVIGNE | N17: 6.8 | O17: 1 | P17: Hors zone (Paris) | U17: https://atalian.com/nos-offres-demploi/ | V17: https://atalian.com/ | X17: Formulaire / site carrières (pas d'email publié)
A18: NET PLUS | C18: 412766206 | D18: Nettoyage courant des bâtiments | E18: 81.21Z | F18: Services administratifs et de soutien | G18: 500-999 | H18: 1 000-1 999 | I18: GE | J18: SAS | K18: RUE DE LA RIGOURDIERE 35510 CESSON-SEVIGNE | L18: 35510 | M18: CESSON-SEVIGNE | N18: 7.7 | O18: 1 | P18: Dans la zone | Q18: contact@net-plus.fr | T18: contact@net-plus.fr | U18: https://net-plus.nous-recrutons.fr/ | V18: https://www.net-plus.fr/ | W18: https://www.net-plus.fr/contact-entreprise-nettoyage/ | X18: Email de contact général trouvé
A19: M-EXTEND FRANCE (MANIP') | C19: 639200260 | D19: Fabrication de matériel de levage et de manutention | E19: 28.22Z | F19: Industrie manufacturière | G19: 500-999 | H19: 500-999 | I19: ETI | J19: SAS | K19: 19 RUE DE RENNES 35690 ACIGNE | L19: 35690 | M19: ACIGNE | N19: 10.3 | O19: 1 | P19: Dans la zone | X19: Recherché, aucun site trouvé
A20: CANON BRETAGNE | C20: 327991774 | D20: Fabrication de machines et d'équipements de bureau (à l'exception des ordinateurs et équipements périphériques) | E20: 28.23Z | F20: Industrie manufacturière | G20: 500-999 | H20: 500-999 | I20: ETI | J20: SAS | K20: LA LANDE DE BEAUGE 35340 LIFFRE | L20: 35340 | M20: LIFFRE | N20: 18.5 | O20: 1 | P20: Dans la zone | Q20: info@cb.canon.fr | T20: info@cb.canon.fr | U20: https://www.canon-bretagne.fr/recrutement/ | V20: https://www.canon-bretagne.fr | W20: https://www.canon-bretagne.fr/mentions-legales/ | X20: Email de contact général trouvé
A21: SANDEN MANUFACTURING EUROPE | C21: 400752028 | D21: Fabrication d'autres pompes et compresseurs | E21: 28.13Z | F21: Industrie manufacturière | G21: 500-999 | H21: 500-999 | I21: ETI | J21: SAS | K21: LD LE QUILLIOU 35190 TINTENIAC | L21: 35190 | M21: TINTENIAC | N21: 23.2 | O21: 1 | P21: Dans la zone | X21: Recherché, aucun site trouvé
A22: PRESTA BREIZH | C22: 393062963 | D22: Transformation et conservation de la viande de boucherie | E22: 10.11Z | F22: Industrie manufacturière | G22: 500-999 | H22: 500-999 | I22: ETI | J22: SAS | K22: ZA DE LA GAUTRAIS 35360 MONTAUBAN-DE-BRETAGNE | L22: 35360 | M22: MONTAUBAN-DE-BRETAGNE | N22: 27.7 | O22: 1 | P22: Dans la zone | Q22: info@prestabreizh.fr | T22: info@prestabreizh.fr | U22: https://careers.werecruit.io/presta-breizh | V22: https://www.prestabreizh.fr/ | W22: https://www.prestabreizh.fr/ | X22: Email de contact général trouvé
A23: KINOUGARDE | C23: 523371052 | D23: Accueil de jeunes enfants | E23: 88.91A | F23: Santé humaine et action sociale | G23: 250-499 | H23: 10 000 et + | I23: ETI | J23: SAS | K23: 39 BOULEVARD DE LA LIBERTE 35000 RENNES | L23: 35000 | M23: RENNES | N23: 0.4 | O23: 1 | P23: Hors zone (Paris) | X23: Recherché, aucun site trouvé
A24: CAISS PRIMA ASSUR MALADIE ILLE & VILAINE | C24: 777749342 | D24: Activités générales de sécurité sociale | E24: 84.30A | F24: Administration publique | G24: 250-499 | H24: 500-999 | I24: ETI | J24: Organisme de sécurité sociale | K24: 7 COURS DES ALLIES 35000 RENNES | L24: 35000 | M24: RENNES | N24: 0.7 | O24: 7 | P24: Dans la zone | Q24: ces@cpam-rennes.cnamts.fr | T24: ces@cpam-rennes.cnamts.fr | U24: https://careers.werecruit.io/fr/cpam-dille-et-vilaine/offres/candidature-spontanee-d726fa | W24: OpenStreetMap | X24: Email de contact général trouvé
A25: CAISSE D ALLOCATIONS FAMILIALES D ILLE ET VILAINE (CAF 35) | C25: 777749375 | D25: Distribution sociale de revenus | E25: 84.30C | F25: Administration publique | G25: 250-499 | H25: 250-499 | I25: ETI | J25: Organisme de sécurité sociale | K25: COURS DES ALLIES 35000 RENNES | L25: 35000 | M25: RENNES | N25: 0.7 | O25: 4 | P25: Dans la zone | V25: https://www.caf.fr/ | X25: Site analysé, aucun email publié
A26: FONDATION SAINT-HELIER | B26: POLE MEDECINE PHYSIQUE READAPTATION SAINT HELIER | C26: 504545443 | D26: Activités hospitalières | E26: 86.10Z | F26: Santé humaine et action sociale | G26: 250-499 | H26: 500-999 | I26: ETI | J26: Association | K26: 54 RUE SAINT-HELIER 35000 RENNES | L26: 35000 | M26: RENNES | N26: 0.9 | O26: 3 | P26: Hors zone (Saint-Jacut-Les-Pins) | Q26: accueil.residence@pole-sthelier.com | T26: accueil.residence@pole-sthelier.com | U26: https://www.pole-sthelier.fr/professionnel/ | V26: https://www.pole-sthelier.fr/ | W26: https://data.rennesmetropole.fr/explore/dataset/sites_organismes_organismes/ | X26: Email de contact général trouvé
A27: NEOTOA (HABITAT 35) | C27: 347498370 | D27: Location de logements | E27: 68.20A | F27: Activités immobilières | G27: 250-499 | H27: 250-499 | I27: ETI | J27: EPIC / entreprise publique | K27: 41 BOULEVARD DE VERDUN 35000 RENNES | L27: 35000 | M27: RENNES | N27: 1 | O27: 1 | P27: Dans la zone | Q27: contact@neotoa.fr | T27: contact@neotoa.fr | U27: https://www.neotoa.fr/nous-rejoindre/ | V27: https://www.neotoa.fr/ | W27: OpenStreetMap | X27: Email de contact général trouvé
A28: NIJI | C28: 439055278 | D28: Conseil en systèmes et logiciels informatiques | E28: 62.02A | F28: Information et communication | G28: 250-499 | H28: 1 000-1 999 | I28: ETI | J28: SAS | K28: IDENTITY 1 9 RUE DE CHATILLON 35000 RENNES | L28: 35000 | M28: RENNES | N28: 1.1 | O28: 1 | P28: Dans la zone | V28: https://www.niji.fr | X28: Site analysé, aucun email publié
A29: BOUCHERS SERVICES | C29: 317238061 | D29: Transformation et conservation de la viande de boucherie | E29: 10.11Z | F29: Industrie manufacturière | G29: 250-499 | H29: 1 000-1 999 | I29: ETI | J29: SAS | K29: 2 RUE DE LA MABILAIS 35000 RENNES | L29: 35000 | M29: RENNES | N29: 1.2 | O29: 2 | P29: Dans la zone | Q29: recrutement@bouchers-services.com | R29: recrutement@bouchers-services.com | W29: Overture Maps (données ouvertes, fiche lieu « Bouchers Services ») | X29: Email RH / recrutement trouvé
A30: HELLOWORK | C30: 428843130 | D30: Traitement de données, hébergement et activités connexes | E30: 63.11Z | F30: Information et communication | G30: 250-499 | H30: 500-999 | I30: ETI | J30: SAS | K30: 2 RUE DE LA MABILAIS 35000 RENNES | L30: 35000 | M30: RENNES | N30: 1.2 | O30: 1 | P30: Dans la zone | U30: https://carrieres.hellowork-group.com/ | V30: https://www.hellowork-group.com/fr/ | X30: Formulaire / site carrières (pas d'email publié)
A31: OEUVRES AUGUSTINES ST YVES | C31: 302819784 | D31: Activités hospitalières | E31: 86.10Z | F31: Santé humaine et action sociale | G31: 250-499 | H31: 250-499 | I31: PME | J31: Association | K31: 4 RUE ADOLPHE LERAY 35000 RENNES | L31: 35000 | M31: RENNES | N31: 1.7 | O31: 1 | P31: Dans la zone | Q31: contact@clinique-styves.fr | T31: contact@clinique-styves.fr | U31: http://www.clinique-styves.fr/offres-emploi/ | V31: https://www.clinique-styves.fr/ | W31: OpenStreetMap | X31: Email de contact général trouvé
A32: ENEDIS | C32: 444608442 | D32: Distribution d'électricité | E32: 35.13Z | F32: Énergie (électricité, gaz, vapeur) | G32: 250-499 | H32: 10 000 et + | I32: GE | J32: SA | K32: 64 BOULEVARD VOLTAIRE 35000 RENNES | L32: 35000 | M32: RENNES | N32: 1.8 | O32: 1 | P32: Hors zone (Puteaux) | U32: https://www.enedis.fr/hub-carriere | V32: https://www.enedis.fr/ | X32: Formulaire / site carrières (pas d'email publié)
A33: GROUPE RENNES SCHOOL OF BUSINESS (ESC RENNES) | C33: 378327514 | D33: Enseignement supérieur | E33: 85.42Z | F33: Enseignement | G33: 250-499 | H33: 250-499 | I33: ETI | J33: Association | K33: 2 RUE ROBERT D'ARBRISSEL 35000 RENNES | L33: 35000 | M33: RENNES | N33: 2.1 | O33: 2 | P33: Dans la zone | Q33: esc@esc-rennes.fr | T33: esc@esc-rennes.fr | V33: https://www.esc-rennes.fr | W33: https://data.rennesmetropole.fr/explore/dataset/sites_organismes_organismes/ | X33: Email de contact général trouvé
A34: OPH RENNES METROPOLE ARCHIPEL HABITAT | C34: 452200751 | D34: Location de logements | E34: 68.20A | F34: Activités immobilières | G34: 250-499 | H34: 250-499 | I34: ETI | J34: EPIC / entreprise publique | K34: 3 PLACE DE LA COMMUNAUTE 35000 RENNES | L34: 35000 | M34: RENNES | N34: 2.1 | O34: 1 | P34: Dans la zone | Q34: contact@archipel-habitat.fr | T34: contact@archipel-habitat.fr | U34: https://www.archipel-habitat.fr/nous-rejoindre/archipel-habitat-employeur | V34: https://www.archipel-habitat.fr/ | W34: OpenStreetMap | X34: Email de contact général trouvé
A35: HOPITAL A DOMICILE 35 SIEGE ADMINISTRATIF | C35: 450741640 | D35: Activités hospitalières | E35: 86.10Z | F35: Santé humaine et action sociale | G35: 250-499 | H35: 250-499 | I35: PME | J35: Association | K35: 7 RUE JULES MAILLARD DE LA GOURNERIE 35000 RENNES | L35: 35000 | M35: RENNES | N35: 2.5 | O35: 1 | P35: Dans la zone | Q35: admission@had35.fr | T35: admission@had35.fr | U35: https://had35.fr/nous-rejoindre/ | V35: https://had35.fr/ | W35: https://had35.fr/ | X35: Email de contact général trouvé
A36: ESPACIL HABITAT SA D'HABITATIONS A LOYER MODERE | C36: 302494398 | D36: Activités des sièges sociaux | E36: 70.10Z | F36: Activités immobilières | G36: 250-499 | H36: 250-499 | I36: GE | J36: SA | K36: 20 RUE GUY ROPARTZ 35700 RENNES | L36: 35700 | M36: RENNES | N36: 2.7 | O36: 1 | P36: Dans la zone | U36: https://www.espacil.com/espacil/recrutement | V36: https://www.espacil.com/ | X36: Formulaire / site carrières (pas d'email publié)
A37: RENOUEST | B37: LECLERC | C37: 305008476 | D37: Hypermarchés | E37: 47.11F | F37: Commerce, réparation auto/moto | G37: 250-499 | H37: 250-499 | I37: ETI | J37: SAS | K37: CENTRE COMMERCIAL CLEUNAY RUE JULES VALLES 35000 RENNES | L37: 35000 | M37: RENNES | N37: 2.7 | O37: 2 | P37: Dans la zone | V37: https://www.e.leclerc/mag/e-leclerc-cleunay | X37: Site analysé, aucun email publié
A38: AVANSSUR | C38: 378393946 | D38: Activités des agents et courtiers d'assurances | E38: 66.22Z | F38: Activités financières et d'assurance | G38: 250-499 | H38: 500-999 | I38: GE | J38: SA | K38: BATIMENT ALCYONE 1 RUE ANDRE ET YVONNE MEYNIER 35000 RENNES | L38: 35000 | M38: RENNES | N38: 2.8 | O38: 1 | P38: Hors zone (Suresnes) | U38: https://www.direct-assurance.fr/recrutement | V38: http://www.direct-assurance.fr | X38: Formulaire / site carrières (pas d'email publié)
A39: URSSAF BRETAGNE | C39: 753759570 | D39: Activités générales de sécurité sociale | E39: 84.30A | F39: Administration publique | G39: 250-499 | H39: 500-999 | I39: ETI | J39: Organisme de sécurité sociale | K39: PARC ALCYONE-BATIMENT E 1 RUE ANDRE ET YVONNE MEYNIER 35000 RENNES | L39: 35000 | M39: RENNES | N39: 2.8 | O39: 1 | P39: Dans la zone | X39: Recherché, aucun site trouvé
A40: SODIRENNES TPLM | C40: 320292204 | D40: Hypermarchés | E40: 47.11F | F40: Commerce, réparation auto/moto | G40: 250-499 | H40: 250-499 | I40: ETI | J40: SAS | K40: ZONE INDUSTRIELLE RUE DE L'ETANG AU DIABLE 35760 SAINT-GREGOIRE | L40: 35760 | M40: SAINT-GREGOIRE | N40: 3.1 | O40: 2 | P40: Dans la zone | V40: https://www.e.leclerc/mag/e-leclerc-saint-gregoire | X40: Site analysé, aucun email publié
...

Sheet Synthèse
A1: Entreprises de 10 salariés et plus à moins de 30 km de Rennes
A3: Indicateur | B3: Nombre
A4: Entreprises listées | B4: =COUNTA(Entreprises!$C$2:$C$4332) -> 4331
A5: Avec un email pour candidater | B5: =COUNTIF(Entreprises!$Q$2:$Q$4332,"?*") -> 1966
A6: dont email RH / recrutement | B6: =COUNTIF(Entreprises!$R$2:$R$4332,"?*") -> 88
A7: dont email SI / informatique | B7: =COUNTIF(Entreprises!$S$2:$S$4332,"?*") -> 1
A8: Avec un email de contact général | B8: =COUNTIF(Entreprises!$T$2:$T$4332,"?*") -> 1925
A9: Avec une page carrières / candidature | B9: =COUNTIF(Entreprises!$U$2:$U$4332,"?*") -> 783
A10: Avec un site web identifié | B10: =COUNTIF(Entreprises!$V$2:$V$4332,"?*") -> 1803
A12: Statut de la recherche
A13: Email RH / recrutement trouvé | B13: =COUNTIF(Entreprises!$X$2:$X$4332,A13) -> 88
A14: Email SI / informatique trouvé | B14: =COUNTIF(Entreprises!$X$2:$X$4332,A14) -> 1
A15: Email de contact général trouvé | B15: =COUNTIF(Entreprises!$X$2:$X$4332,A15) -> 1877
A16: Formulaire / site carrières (pas d'email publié) | B16: =COUNTIF(Entreprises!$X$2:$X$4332,A16) -> 147
A17: Site analysé, aucun email publié | B17: =COUNTIF(Entreprises!$X$2:$X$4332,A17) -> 231
A18: Recherché, aucun site trouvé | B18: =COUNTIF(Entreprises!$X$2:$X$4332,A18) -> 156
A19: Site trouvé, pas encore analysé | B19: =COUNTIF(Entreprises!$X$2:$X$4332,A19) -> 102
A20: Pas encore recherché | B20: =COUNTIF(Entreprises!$X$2:$X$4332,A20) -> 1653
A22: Effectif local (tranche INSEE) | B22: Entreprises | C22: dont avec email
A23: 10-19 | B23: =COUNTIF(Entreprises!$G$2:$G$4332,A23)+COUNTIF(Entreprises!$G$2:$G$4332,A23&" (estim.)") -> 2119 | C23: =COUNTIFS(Entreprises!$G$2:$G$4332,A23,Entreprises!$Q$2:$Q$4332,"?*")+COUNTIFS(Entreprises!$G$2:$G$4332,A23&" (estim.)",Entreprises!$Q$2:$Q$4332,"?*") -> 852
A24: 20-49 | B24: =COUNTIF(Entreprises!$G$2:$G$4332,A24)+COUNTIF(Entreprises!$G$2:$G$4332,A24&" (estim.)") -> 1394 | C24: =COUNTIFS(Entreprises!$G$2:$G$4332,A24,Entreprises!$Q$2:$Q$4332,"?*")+COUNTIFS(Entreprises!$G$2:$G$4332,A24&" (estim.)",Entreprises!$Q$2:$Q$4332,"?*") -> 686
A25: 50-99 | B25: =COUNTIF(Entreprises!$G$2:$G$4332,A25)+COUNTIF(Entreprises!$G$2:$G$4332,A25&" (estim.)") -> 491 | C25: =COUNTIFS(Entreprises!$G$2:$G$4332,A25,Entreprises!$Q$2:$Q$4332,"?*")+COUNTIFS(Entreprises!$G$2:$G$4332,A25&" (estim.)",Entreprises!$Q$2:$Q$4332,"?*") -> 277
A26: 100-199 | B26: =COUNTIF(Entreprises!$G$2:$G$4332,A26)+COUNTIF(Entreprises!$G$2:$G$4332,A26&" (estim.)") -> 212 | C26: =COUNTIFS(Entreprises!$G$2:$G$4332,A26,Entreprises!$Q$2:$Q$4332,"?*")+COUNTIFS(Entreprises!$G$2:$G$4332,A26&" (estim.)",Entreprises!$Q$2:$Q$4332,"?*") -> 102
A27: 200-249 | B27: =COUNTIF(Entreprises!$G$2:$G$4332,A27)+COUNTIF(Entreprises!$G$2:$G$4332,A27&" (estim.)") -> 37 | C27: =COUNTIFS(Entreprises!$G$2:$G$4332,A27,Entreprises!$Q$2:$Q$4332,"?*")+COUNTIFS(Entreprises!$G$2:$G$4332,A27&" (estim.)",Entreprises!$Q$2:$Q$4332,"?*") -> 16
A28: 250-499 | B28: =COUNTIF(Entreprises!$G$2:$G$4332,A28)+COUNTIF(Entreprises!$G$2:$G$4332,A28&" (estim.)") -> 57 | C28: =COUNTIFS(Entreprises!$G$2:$G$4332,A28,Entreprises!$Q$2:$Q$4332,"?*")+COUNTIFS(Entreprises!$G$2:$G$4332,A28&" (estim.)",Entreprises!$Q$2:$Q$4332,"?*") -> 23
A29: 500-999 | B29: =COUNTIF(Entreprises!$G$2:$G$4332,A29)+COUNTIF(Entreprises!$G$2:$G$4332,A29&" (estim.)") -> 15 | C29: =COUNTIFS(Entreprises!$G$2:$G$4332,A29,Entreprises!$Q$2:$Q$4332,"?*")+COUNTIFS(Entreprises!$G$2:$G$4332,A29&" (estim.)",Entreprises!$Q$2:$Q$4332,"?*") -> 10
A30: 1 000-1 999 | B30: =COUNTIF(Entreprises!$G$2:$G$4332,A30)+COUNTIF(Entreprises!$G$2:$G$4332,A30&" (estim.)") -> 6 | C30: =COUNTIFS(Entreprises!$G$2:$G$4332,A30,Entreprises!$Q$2:$Q$4332,"?*")+COUNTIFS(Entreprises!$G$2:$G$4332,A30&" (estim.)",Entreprises!$Q$2:$Q$4332,"?*") -> 0
A32: Secteur | B32: Entreprises | C32: dont avec email
A33: Activités financières et d'assurance | B33: =COUNTIF(Entreprises!$F$2:$F$4332,A33) -> 127 | C33: =COUNTIFS(Entreprises!$F$2:$F$4332,A33,Entreprises!$Q$2:$Q$4332,"?*") -> 35
A34: Activités immobilières | B34: =COUNTIF(Entreprises!$F$2:$F$4332,A34) -> 55 | C34: =COUNTIFS(Entreprises!$F$2:$F$4332,A34,Entreprises!$Q$2:$Q$4332,"?*") -> 30
A35: Activités spécialisées, scientifiques et techniques | B35: =COUNTIF(Entreprises!$F$2:$F$4332,A35) -> 474 | C35: =COUNTIFS(Entreprises!$F$2:$F$4332,A35,Entreprises!$Q$2:$Q$4332,"?*") -> 206
A36: Administration publique | B36: =COUNTIF(Entreprises!$F$2:$F$4332,A36) -> 17 | C36: =COUNTIFS(Entreprises!$F$2:$F$4332,A36,Entreprises!$Q$2:$Q$4332,"?*") -> 8
A37: Agriculture, sylviculture et pêche | B37: =COUNTIF(Entreprises!$F$2:$F$4332,A37) -> 43 | C37: =COUNTIFS(Entreprises!$F$2:$F$4332,A37,Entreprises!$Q$2:$Q$4332,"?*") -> 13
A38: Arts, spectacles et activités récréatives | B38: =COUNTIF(Entreprises!$F$2:$F$4332,A38) -> 99 | C38: =COUNTIFS(Entreprises!$F$2:$F$4332,A38,Entreprises!$Q$2:$Q$4332,"?*") -> 68
A39: Autres activités de services | B39: =COUNTIF(Entreprises!$F$2:$F$4332,A39) -> 145 | C39: =COUNTIFS(Entreprises!$F$2:$F$4332,A39,Entreprises!$Q$2:$Q$4332,"?*") -> 84
A40: Commerce, réparation auto/moto | B40: =COUNTIF(Entreprises!$F$2:$F$4332,A40) -> 749 | C40: =COUNTIFS(Entreprises!$F$2:$F$4332,A40,Entreprises!$Q$2:$Q$4332,"?*") -> 285
A41: Construction | B41: =COUNTIF(Entreprises!$F$2:$F$4332,A41) -> 478 | C41: =COUNTIFS(Entreprises!$F$2:$F$4332,A41,Entreprises!$Q$2:$Q$4332,"?*") -> 231
A42: Eau, assainissement, déchets, dépollution | B42: =COUNTIF(Entreprises!$F$2:$F$4332,A42) -> 26 | C42: =COUNTIFS(Entreprises!$F$2:$F$4332,A42,Entreprises!$Q$2:$Q$4332,"?*") -> 9
A43: Enseignement | B43: =COUNTIF(Entreprises!$F$2:$F$4332,A43) -> 236 | C43: =COUNTIFS(Entreprises!$F$2:$F$4332,A43,Entreprises!$Q$2:$Q$4332,"?*") -> 207
A44: Hébergement et restauration | B44: =COUNTIF(Entreprises!$F$2:$F$4332,A44) -> 374 | C44: =COUNTIFS(Entreprises!$F$2:$F$4332,A44,Entreprises!$Q$2:$Q$4332,"?*") -> 175
...

Sheet Méthode et limites
A1: Méthode et limites
A3: Périmètre
A4: Établissements actifs situés à 30 km ou moins de l'hôtel de ville de Rennes, comptant au moins 10 salariés sur place (tranche d'effectif INSEE de l'établissement). Une ligne par entreprise (SIREN) ; l'adresse affichée est celle de son plus gros établissement dans la zone. Quand l'effectif local n'est pas renseigné pour une entreprise mono-site, l'effectif de l'entreprise est repris, signalé « (estim.) ».
A5: Tous secteurs privés, associations et entreprises publiques (EPIC) compris. Administrations, collectivités et établissements publics administratifs exclus (secteur public non retenu).
A7: Sources
A8: Liste des entreprises : base SIRENE (INSEE) via l'API Recherche d'entreprises de l'État, extraction du 18/10/2026. Licence Ouverte Etalab.
A9: Sites web et emails : sites officiels des entreprises (pages accueil, contact, recrutement, mentions légales), liste des entreprises RGE de l'ADEME (Licence Ouverte), Wikidata (CC0) et OpenStreetMap (© contributeurs OpenStreetMap, licence ODbL).
A10: Annuaires officiels utilisés en complément : annuaire de l'Éducation nationale (data.education.gouv.fr, Licence Ouverte) pour les écoles privées (OGEC), Annuaire social du Département d'Ille-et-Vilaine, annuaires des communes (Pacé, Noyal-Châtillon-sur-Seiche, Chartres-de-Bretagne, Châteaubourg, L'Hermitage, Guichen, Louvigné-de-Bais…), annuaire de la CRESS Bretagne, Chambre des notaires, et DATAtourisme (sites web des restaurants et hôtels).
A11: Ajouts récents : référentiel « Sites et organismes » de Rennes Métropole (data.rennesmetropole.fr), jeux de données ouverts de la Région Bretagne (data.bretagne.bzh), Plateforme de l'inclusion (structures d'insertion), annuaire OPQIBI (ingénierie), annuaires des membres du Poool (French Tech Rennes) et de Produit en Bretagne (sites web), annuaires de La Mézière, Vern-sur-Seiche, Saint-Gilles, Bréal-sous-Montfort, Melesse, Liffré-Cormier, Servon, annuaire des organismes de formation du GREF Bretagne. Pour quelques filiales de groupes installées au siège du groupe (Samsic, Legendre), l'adresse est celle du groupe.
A12: Données Overture Maps Foundation (lieux, édition 2026-09, licences CDLA-Permissive / ODbL) : adresses et sites publiés sur les fiches publiques des établissements, rapprochées par nom et position GPS (moins de 300 m en général) puis vérifiées une à une ; la colonne « Source des emails » cite la fiche utilisée. Quand l'adresse trouvée est celle du groupe ou de l'enseigne (ex. magasin d'une chaîne), la note « groupe » est indiquée.
A13: La colonne « Source des emails » indique la page ou le jeu de données d'où proviennent les adresses.
A15: Colonnes de contact
... A25: Pour des candidatures, privilégie des messages individuels et personnalisés plutôt qu'un envoi groupé, qui finit souvent en spam.
